Workbook

Sheet Prices
C4: Date | D4: Fund_Price | E4: Benchmark_Price
C5: 42005 | D5: 165.62384 | E5: 1994.99
C6: 42036 | D6: 174.93259 | E6: 2104.5
C7: 42064 | D7: 171.41997 | E7: 2067.8899
C8: 42095 | D8: 173.87842 | E8: 2085.51
C9: 42125 | D9: 176.11386 | E9: 2107.3899
C10: 42156 | D10: 171.7014 | E10: 2063.1101
C11: 42186 | D11: 176.43405 | E11: 2103.8401
C12: 42217 | D12: 165.68037 | E12: 1972.1801
C13: 42248 | D13: 160.61794 | E13: 1920.03
C14: 42278 | D14: 175.18605 | E14: 2079.3601
C15: 42309 | D15: 175.8264 | E15: 2080.4099
C16: 42339 | D16: 171.76547 | E16: 2043.9399
... C138: 46054 | D138: 689.42999 | E138: 6909.5098

Sheet Returns
C4: Date | D4: Fund_Price | E4: Benchmark_Price | F4: Fund_Return | G4: Bench_Return | H4: Active_Return | I4: Fund_Growth | J4: Benchmark_Growth | K4: Rolling_12M_Fund | L4: Rolling_12M_Benchmark | M4: Highest Val | N4: Drawdown | O4: Column1
C5: 42005 | D5: 165.62384 | E5: 1994.99 | F5: =IFERROR((General[[#This Row],[Fund_Price]]-D4)/D4,0) -> 0 | G5: =IFERROR((General[[#This Row],[Benchmark_Price]]-E4)/E4,0) -> 0 | H5: =General[[#This Row],[Fund_Return]]-General[[#This Row],[Bench_Return]] -> 0 | I5: =1000 -> 1000 | J5: 1000 | M5: =General[[#This Row],[Fund_Price]] -> 165.62384 | N5: =(General[[#This Row],[Fund_Price]]-General[[#This Row],[Highest Val]])/General[[#This Row],[Highest Val]] -> 0 | O5: =MIN(General[Drawdown]) -> -0.23972222
C6: 42036 | D6: 174.93259 | E6: 2104.5 | F6: =IFERROR((General[[#This Row],[Fund_Price]]-D5)/D5,0) -> 0.056204145 | G6: =IFERROR((General[[#This Row],[Benchmark_Price]]-E5)/E5,0) -> 0.054892511 | H6: =General[[#This Row],[Fund_Return]]-General[[#This Row],[Bench_Return]] -> 0.0013116341 | I6: =I5*(1+General[[#This Row],[Fund_Return]]) -> 1056.2041 | J6: =J5*(1+General[[#This Row],[Bench_Return]]) -> 1054.8925 | M6: =MAX(M5,General[[#This Row],[Fund_Price]]) -> 174.93259 | N6: =(General[[#This Row],[Fund_Price]]-General[[#This Row],[Highest Val]])/General[[#This Row],[Highest Val]] -> 0
C7: 42064 | D7: 171.41997 | E7: 2067.8899 | F7: =IFERROR((General[[#This Row],[Fund_Price]]-D6)/D6,0) -> -0.020079844 | G7: =IFERROR((General[[#This Row],[Benchmark_Price]]-E6)/E6,0) -> -0.017396107 | H7: =General[[#This Row],[Fund_Return]]-General[[#This Row],[Bench_Return]] -> -0.0026837367 | I7: =I6*(1+General[[#This Row],[Fund_Return]]) -> 1034.9957 | J7: =J6*(1+General[[#This Row],[Bench_Return]]) -> 1036.5415 | M7: =MAX(M6,General[[#This Row],[Fund_Price]]) -> 174.93259 | N7: =(General[[#This Row],[Fund_Price]]-General[[#This Row],[Highest Val]])/General[[#This Row],[Highest Val]] -> -0.020079844
C8: 42095 | D8: 173.87842 | E8: 2085.51 | F8: =IFERROR((General[[#This Row],[Fund_Price]]-D7)/D7,0) -> 0.01434168 | G8: =IFERROR((General[[#This Row],[Benchmark_Price]]-E7)/E7,0) -> 0.0085208198 | H8: =General[[#This Row],[Fund_Return]]-General[[#This Row],[Bench_Return]] -> 0.0058208602 | I8: =I7*(1+General[[#This Row],[Fund_Return]]) -> 1049.8393 | J8: =J7*(1+General[[#This Row],[Bench_Return]]) -> 1045.3737 | M8: =MAX(M7,General[[#This Row],[Fund_Price]]) -> 174.93259 | N8: =(General[[#This Row],[Fund_Price]]-General[[#This Row],[Highest Val]])/General[[#This Row],[Highest Val]] -> -0.0060261425
C9: 42125 | D9: 176.11386 | E9: 2107.3899 | F9: =IFERROR((General[[#This Row],[Fund_Price]]-D8)/D8,0) -> 0.012856358 | G9: =IFERROR((General[[#This Row],[Benchmark_Price]]-E8)/E8,0) -> 0.010491382 | H9: =General[[#This Row],[Fund_Return]]-General[[#This Row],[Bench_Return]] -> 0.0023649753 | I9: =I8*(1+General[[#This Row],[Fund_Return]]) -> 1063.3364 | J9: =J8*(1+General[[#This Row],[Bench_Return]]) -> 1056.3411 | M9: =MAX(M8,General[[#This Row],[Fund_Price]]) -> 176.11386 | N9: =(General[[#This Row],[Fund_Price]]-General[[#This Row],[Highest Val]])/General[[#This Row],[Highest Val]] -> 0
C10: 42156 | D10: 171.7014 | E10: 2063.1101 | F10: =IFERROR((General[[#This Row],[Fund_Price]]-D9)/D9,0) -> -0.025054589 | G10: =IFERROR((General[[#This Row],[Benchmark_Price]]-E9)/E9,0) -> -0.021011672 | H10: =General[[#This Row],[Fund_Return]]-General[[#This Row],[Bench_Return]] -> -0.0040429166 | I10: =I9*(1+General[[#This Row],[Fund_Return]]) -> 1036.695 | J10: =J9*(1+General[[#This Row],[Bench_Return]]) -> 1034.1456 | M10: =MAX(M9,General[[#This Row],[Fund_Price]]) -> 176.11386 | N10: =(General[[#This Row],[Fund_Price]]-General[[#This Row],[Highest Val]])/General[[#This Row],[Highest Val]] -> -0.025054589
C11: 42186 | D11: 176.43405 | E11: 2103.8401 | F11: =IFERROR((General[[#This Row],[Fund_Price]]-D10)/D10,0) -> 0.027563262 | G11: =IFERROR((General[[#This Row],[Benchmark_Price]]-E10)/E10,0) -> 0.019742029 | H11: =General[[#This Row],[Fund_Return]]-General[[#This Row],[Bench_Return]] -> 0.0078212329 | I11: =I10*(1+General[[#This Row],[Fund_Return]]) -> 1065.2697 | J11: =J10*(1+General[[#This Row],[Bench_Return]]) -> 1054.5617 | M11: =MAX(M10,General[[#This Row],[Fund_Price]]) -> 176.43405 | N11: =(General[[#This Row],[Fund_Price]]-General[[#This Row],[Highest Val]])/General[[#This Row],[Highest Val]] -> 0
C12: 42217 | D12: 165.68037 | E12: 1972.1801 | F12: =IFERROR((General[[#This Row],[Fund_Price]]-D11)/D11,0) -> -0.060950124 | G12: =IFERROR((General[[#This Row],[Benchmark_Price]]-E11)/E11,0) -> -0.062580818 | H12: =General[[#This Row],[Fund_Return]]-General[[#This Row],[Bench_Return]] -> 0.001630694 | I12: =I11*(1+General[[#This Row],[Fund_Return]]) -> 1000.3413 | J12: =J11*(1+General[[#This Row],[Bench_Return]]) -> 988.56639 | M12: =MAX(M11,General[[#This Row],[Fund_Price]]) -> 176.43405 | N12: =(General[[#This Row],[Fund_Price]]-General[[#This Row],[Highest Val]])/General[[#This Row],[Highest Val]] -> -0.060950124
C13: 42248 | D13: 160.61794 | E13: 1920.03 | F13: =IFERROR((General[[#This Row],[Fund_Price]]-D12)/D12,0) -> -0.030555453 | G13: =IFERROR((General[[#This Row],[Benchmark_Price]]-E12)/E12,0) -> -0.026442831 | H13: =General[[#This Row],[Fund_Return]]-General[[#This Row],[Bench_Return]] -> -0.0041126222 | I13: =I12*(1+General[[#This Row],[Fund_Return]]) -> 969.77546 | J13: =J12*(1+General[[#This Row],[Bench_Return]]) -> 962.4259 | M13: =MAX(M12,General[[#This Row],[Fund_Price]]) -> 176.43405 | N13: =(General[[#This Row],[Fund_Price]]-General[[#This Row],[Highest Val]])/General[[#This Row],[Highest Val]] -> -0.089643219
C14: 42278 | D14: 175.18605 | E14: 2079.3601 | F14: =IFERROR((General[[#This Row],[Fund_Price]]-D13)/D13,0) -> 0.090700427 | G14: =IFERROR((General[[#This Row],[Benchmark_Price]]-E13)/E13,0) -> 0.082983118 | H14: =General[[#This Row],[Fund_Return]]-General[[#This Row],[Bench_Return]] -> 0.0077173087 | I14: =I13*(1+General[[#This Row],[Fund_Return]]) -> 1057.7345 | J14: =J13*(1+General[[#This Row],[Bench_Return]]) -> 1042.291 | M14: =MAX(M13,General[[#This Row],[Fund_Price]]) -> 176.43405 | N14: =(General[[#This Row],[Fund_Price]]-General[[#This Row],[Highest Val]])/General[[#This Row],[Highest Val]] -> -0.0070734707
C15: 42309 | D15: 175.8264 | E15: 2080.4099 | F15: =IFERROR((General[[#This Row],[Fund_Price]]-D14)/D14,0) -> 0.0036552587 | G15: =IFERROR((General[[#This Row],[Benchmark_Price]]-E14)/E14,0) -> 0.00050486911 | H15: =General[[#This Row],[Fund_Return]]-General[[#This Row],[Bench_Return]] -> 0.0031503896 | I15: =I14*(1+General[[#This Row],[Fund_Return]]) -> 1061.6008 | J15: =J14*(1+General[[#This Row],[Bench_Return]]) -> 1042.8172 | M15: =MAX(M14,General[[#This Row],[Fund_Price]]) -> 176.43405 | N15: =(General[[#This Row],[Fund_Price]]-General[[#This Row],[Highest Val]])/General[[#This Row],[Highest Val]] -> -0.0034440674
C16: 42339 | D16: 171.76547 | E16: 2043.9399 | F16: =IFERROR((General[[#This Row],[Fund_Price]]-D15)/D15,0) -> -0.023096238 | G16: =IFERROR((General[[#This Row],[Benchmark_Price]]-E15)/E15,0) -> -0.017530185 | H16: =General[[#This Row],[Fund_Return]]-General[[#This Row],[Bench_Return]] -> -0.0055660527 | I16: =I15*(1+General[[#This Row],[Fund_Return]]) -> 1037.0818 | J16: =J15*(1+General[[#This Row],[Bench_Return]]) -> 1024.5364 | M16: =MAX(M15,General[[#This Row],[Fund_Price]]) -> 176.43405 | N16: =(General[[#This Row],[Fund_Price]]-General[[#This Row],[Highest Val]])/General[[#This Row],[Highest Val]] -> -0.02646076
C17: 42370 | D17: 164.18515 | E17: 1940.24 | F17: =IFERROR((General[[#This Row],[Fund_Price]]-D16)/D16,0) -> -0.044131816 | G17: =IFERROR((General[[#This Row],[Benchmark_Price]]-E16)/E16,0) -> -0.050735322 | H17: =General[[#This Row],[Fund_Return]]-General[[#This Row],[Bench_Return]] -> 0.0066035058 | I17: =I16*(1+General[[#This Row],[Fund_Return]]) -> 991.31351 | J17: =J16*(1+General[[#This Row],[Bench_Return]]) -> 972.55625 | K17: =(General[[#This Row],[Fund_Price]]-D5)/D5 -> -0.0086864921 | L17: =(General[[#This Row],[Benchmark_Price]]-E5)/E5 -> -0.027443747 | M17: =MAX(M16,General[[#This Row],[Fund_Price]]) -> 176.43405 | N17: =(General[[#This Row],[Fund_Price]]-General[[#This Row],[Highest Val]])/General[[#This Row],[Highest Val]] -> -0.069424815
C18: 42401 | D18: 164.04953 | E18: 1932.23 | F18: =IFERROR((General[[#This Row],[Fund_Price]]-D17)/D17,0) -> -0.00082601939 | G18: =IFERROR((General[[#This Row],[Benchmark_Price]]-E17)/E17,0) -> -0.0041283603 | H18: =General[[#This Row],[Fund_Return]]-General[[#This Row],[Bench_Return]] -> 0.0033023409 | I18: =I17*(1+General[[#This Row],[Fund_Return]]) -> 990.49466 | J18: =J17*(1+General[[#This Row],[Bench_Return]]) -> 968.54119 | K18: =(General[[#This Row],[Fund_Price]]-D6)/D6 -> -0.062212861 | L18: =(General[[#This Row],[Benchmark_Price]]-E6)/E6 -> -0.081857933 | M18: =MAX(M17,General[[#This Row],[Fund_Price]]) -> 176.43405 | N18: =(General[[#This Row],[Fund_Price]]-General[[#This Row],[Highest Val]])/General[[#This Row],[Highest Val]] -> -0.070193488
C19: 42430 | D19: 174.18608 | E19: 2059.74 | F19: =IFERROR((General[[#This Row],[Fund_Price]]-D18)/D18,0) -> 0.061789576 | G19: =IFERROR((General[[#This Row],[Benchmark_Price]]-E18)/E18,0) -> 0.065991114 | H19: =General[[#This Row],[Fund_Return]]-General[[#This Row],[Bench_Return]] -> -0.0042015384 | I19: =I18*(1+General[[#This Row],[Fund_Return]]) -> 1051.6969 | J19: =J18*(1+General[[#This Row],[Bench_Return]]) -> 1032.4563 | K19: =(General[[#This Row],[Fund_Price]]-D7)/D7 -> 0.016136471 | L19: =(General[[#This Row],[Benchmark_Price]]-E7)/E7 -> -0.0039411684 | M19: =MAX(M18,General[[#This Row],[Fund_Price]]) -> 176.43405 | N19: =(General[[#This Row],[Fund_Price]]-General[[#This Row],[Highest Val]])/General[[#This Row],[Highest Val]] -> -0.012741138
C20: 42461 | D20: 175.77452 | E20: 2065.3 | F20: =IFERROR((General[[#This Row],[Fund_Price]]-D19)/D19,0) -> 0.0091192128 | G20: =IFERROR((General[[#This Row],[Benchmark_Price]]-E19)/E19,0) -> 0.0026993983 | H20: =General[[#This Row],[Fund_Return]]-General[[#This Row],[Bench_Return]] -> 0.0064198145 | I20: =I19*(1+General[[#This Row],[Fund_Return]]) -> 1061.2876 | J20: =J19*(1+General[[#This Row],[Bench_Return]]) -> 1035.2433 | K20: =(General[[#This Row],[Fund_Price]]-D8)/D8 -> 0.010904763 | L20: =(General[[#This Row],[Benchmark_Price]]-E8)/E8 -> -0.0096906564 | M20: =MAX(M19,General[[#This Row],[Fund_Price]]) -> 176.43405 | N20: =(General[[#This Row],[Fund_Price]]-General[[#This Row],[Highest Val]])/General[[#This Row],[Highest Val]] -> -0.0037381142
C21: 42491 | D21: 178.76472 | E21: 2096.95 | F21: =IFERROR((General[[#This Row],[Fund_Price]]-D20)/D20,0) -> 0.017011589 | G21: =IFERROR((General[[#This Row],[Benchmark_Price]]-E20)/E20,0) -> 0.015324603 | H21: =General[[#This Row],[Fund_Return]]-General[[#This Row],[Bench_Return]] -> 0.0016869862 | I21: =I20*(1+General[[#This Row],[Fund_Return]]) -> 1079.3417 | J21: =J20*(1+General[[#This Row],[Bench_Return]]) -> 1051.108 | K21: =(General[[#This Row],[Fund_Price]]-D9)/D9 -> 0.015051988 | L21: =(General[[#This Row],[Benchmark_Price]]-E9)/E9 -> -0.0049539677 | M21: =MAX(M20,General[[#This Row],[Fund_Price]]) -> 178.76472 | N21: =(General[[#This Row],[Fund_Price]]-General[[#This Row],[Highest Val]])/General[[#This Row],[Highest Val]] -> 0
C22: 42522 | D22: 178.45802 | E22: 2098.8601 | F22: =IFERROR((General[[#This Row],[Fund_Price]]-D21)/D21,0) -> -0.0017156722 | G22: =IFERROR((General[[#This Row],[Benchmark_Price]]-E21)/E21,0) -> 0.00091092124 | H22: =General[[#This Row],[Fund_Return]]-General[[#This Row],[Bench_Return]] -> -0.0026265934 | I22: =I21*(1+General[[#This Row],[Fund_Return]]) -> 1077.4899 | J22: =J21*(1+General[[#This Row],[Bench_Return]]) -> 1052.0655 | K22: =(General[[#This Row],[Fund_Price]]-D10)/D10 -> 0.039351003 | L22: =(General[[#This Row],[Benchmark_Price]]-E10)/E10 -> 0.017328207 | M22: =MAX(M21,General[[#This Row],[Fund_Price]]) -> 178.76472 | N22: =(General[[#This Row],[Fund_Price]]-General[[#This Row],[Highest Val]])/General[[#This Row],[Highest Val]] -> -0.0017156722
C23: 42552 | D23: 185.92854 | E23: 2173.6001 | F23: =IFERROR((General[[#This Row],[Fund_Price]]-D22)/D22,0) -> 0.041861497 | G23: =IFERROR((General[[#This Row],[Benchmark_Price]]-E22)/E22,0) -> 0.035609801 | H23: =General[[#This Row],[Fund_Return]]-General[[#This Row],[Bench_Return]] -> 0.0062516964 | I23: =I22*(1+General[[#This Row],[Fund_Return]]) -> 1122.5953 | J23: =J22*(1+General[[#This Row],[Bench_Return]]) -> 1089.5293 | K23: =(General[[#This Row],[Fund_Price]]-D11)/D11 -> 0.053813261 | L23: =(General[[#This Row],[Benchmark_Price]]-E11)/E11 -> 0.033158418 | M23: =MAX(M22,General[[#This Row],[Fund_Price]]) -> 185.92854 | N23: =(General[[#This Row],[Fund_Price]]-General[[#This Row],[Highest Val]])/General[[#This Row],[Highest Val]] -> 0
C24: 42583 | D24: 186.15117 | E24: 2170.95 | F24: =IFERROR((General[[#This Row],[Fund_Price]]-D23)/D23,0) -> 0.0011973725 | G24: =IFERROR((General[[#This Row],[Benchmark_Price]]-E23)/E23,0) -> -0.0012192429 | H24: =General[[#This Row],[Fund_Return]]-General[[#This Row],[Bench_Return]] -> 0.0024166154 | I24: =I23*(1+General[[#This Row],[Fund_Return]]) -> 1123.9395 | J24: =J23*(1+General[[#This Row],[Bench_Return]]) -> 1088.2009 | K24: =(General[[#This Row],[Fund_Price]]-D12)/D12 -> 0.12355594 | L24: =(General[[#This Row],[Benchmark_Price]]-E12)/E12 -> 0.10078689 | M24: =MAX(M23,General[[#This Row],[Fund_Price]]) -> 186.15117 | N24: =(General[[#This Row],[Fund_Price]]-General[[#This Row],[Highest Val]])/General[[#This Row],[Highest Val]] -> 0
C25: 42614 | D25: 185.22635 | E25: 2168.27 | F25: =IFERROR((General[[#This Row],[Fund_Price]]-D24)/D24,0) -> -0.0049681125 | G25: =IFERROR((General[[#This Row],[Benchmark_Price]]-E24)/E24,0) -> -0.0012344511 | H25: =General[[#This Row],[Fund_Return]]-General[[#This Row],[Bench_Return]] -> -0.0037336613 | I25: =I24*(1+General[[#This Row],[Fund_Return]]) -> 1118.3556 | J25: =J24*(1+General[[#This Row],[Bench_Return]]) -> 1086.8576 | K25: =(General[[#This Row],[Fund_Price]]-D13)/D13 -> 0.15321087 | L25: =(General[[#This Row],[Benchmark_Price]]-E13)/E13 -> 0.12928964 | M25: =MAX(M24,General[[#This Row],[Fund_Price]]) -> 186.15117 | N25: =(General[[#This Row],[Fund_Price]]-General[[#This Row],[Highest Val]])/General[[#This Row],[Highest Val]] -> -0.0049681125
C26: 42644 | D26: 182.93451 | E26: 2126.1499 | F26: =IFERROR((General[[#This Row],[Fund_Price]]-D25)/D25,0) -> -0.012373183 | G26: =IFERROR((General[[#This Row],[Benchmark_Price]]-E25)/E25,0) -> -0.019425679 | H26: =General[[#This Row],[Fund_Return]]-General[[#This Row],[Bench_Return]] -> 0.0070524954 | I26: =I25*(1+General[[#This Row],[Fund_Return]]) -> 1104.518 | J26: =J25*(1+General[[#This Row],[Bench_Return]]) -> 1065.7446 | K26: =(General[[#This Row],[Fund_Price]]-D14)/D14 -> 0.044229885 | L26: =(General[[#This Row],[Benchmark_Price]]-E14)/E14 -> 0.022502016 | M26: =MAX(M25,General[[#This Row],[Fund_Price]]) -> 186.15117 | N26: =(General[[#This Row],[Fund_Price]]-General[[#This Row],[Highest Val]])/General[[#This Row],[Highest Val]] -> -0.017279825
C27: 42675 | D27: 189.67346 | E27: 2198.8101 | F27: =IFERROR((General[[#This Row],[Fund_Price]]-D26)/D26,0) -> 0.036838061 | G27: =IFERROR((General[[#This Row],[Benchmark_Price]]-E26)/E26,0) -> 0.034174522 | H27: =General[[#This Row],[Fund_Return]]-General[[#This Row],[Bench_Return]] -> 0.0026635393 | I27: =I26*(1+General[[#This Row],[Fund_Return]]) -> 1145.2063 | J27: =J26*(1+General[[#This Row],[Bench_Return]]) -> 1102.166 | K27: =(General[[#This Row],[Fund_Price]]-D15)/D15 -> 0.078754164 | L27: =(General[[#This Row],[Benchmark_Price]]-E15)/E15 -> 0.056911932 | M27: =MAX(M26,General[[#This Row],[Fund_Price]]) -> 189.67346 | N27: =(General[[#This Row],[Fund_Price]]-General[[#This Row],[Highest Val]])/General[[#This Row],[Highest Val]] -> 0
C28: 42705 | D28: 192.38461 | E28: 2238.8301 | F28: =IFERROR((General[[#This Row],[Fund_Price]]-D27)/D27,0) -> 0.014293782 | G28: =IFERROR((General[[#This Row],[Benchmark_Price]]-E27)/E27,0) -> 0.018200762 | H28: =General[[#This Row],[Fund_Return]]-General[[#This Row],[Bench_Return]] -> -0.0039069804 | I28: =I27*(1+General[[#This Row],[Fund_Return]]) -> 1161.5756 | J28: =J27*(1+General[[#This Row],[Bench_Return]]) -> 1122.2262 | K28: =(General[[#This Row],[Fund_Price]]-D16)/D16 -> 0.12004241 | L28: =(General[[#This Row],[Benchmark_Price]]-E16)/E16 -> 0.095350227 | M28: =MAX(M27,General[[#This Row],[Fund_Price]]) -> 192.38461 | N28: =(General[[#This Row],[Fund_Price]]-General[[#This Row],[Highest Val]])/General[[#This Row],[Highest Val]] -> 0
... C138: 46054 | D138: 689.42999 | E138: 6909.5098 | F138: =IFERROR((General[[#This Row],[Fund_Price]]-D137)/D137,0) -> -0.0036706478 | G138: =IFERROR((General[[#This Row],[Benchmark_Price]]-E137)/E137,0) -> -0.0042541999 | H138: =General[[#This Row],[Fund_Return]]-General[[#This Row],[Bench_Return]] -> 0.00058355209 | I138: =I137*(1+General[[#This Row],[Fund_Return]]) -> 4162.6253 | J138: =J137*(1+General[[#This Row],[Bench_Return]]) -> 3463.4308 | K138: =(General[[#This Row],[Fund_Price]]-D126)/D126 -> 0.17393057 | L138: =(General[[#This Row],[Benchmark_Price]]-E126)/E126 -> 0.16038454 | M138: =MAX(M137,General[[#This Row],[Fund_Price]]) -> 691.96997 | N138: =(General[[#This Row],[Fund_Price]]-General[[#This Row],[Highest Val]])/General[[#This Row],[Highest Val]] -> -0.0036706478

Sheet Summary
C5: Metric | D5: Fund | E5: Benchmark | H5: S.D | I5: =_xlfn.STDEV.S(General[Fund_Return]) -> 0.043609918
C6: YTD | D6: =(Returns!D138-Returns!D137)/Returns!D137 -> -0.0036706478 | E6: =(Returns!E138-Returns!E137)/Returns!E137 -> -0.0042541999 | H6: Annualized | I6: =I5*SQRT(12) -> 0.15106919
C7: 1 Year | D7: =(Returns!D138/Returns!D126)-1 -> 0.17393057 | E7: =(Returns!E138/Returns!E126)-1 -> 0.16038454
C8: 2 Year | D8: =(Returns!D138/Returns!D114)-1 -> 0.3904768 | E8: =(Returns!E138/Returns!E114)-1 -> 0.35579742 | H8: Max DD | I8: =Returns!O5 -> -0.23972222
C9: 3 Year | D9: =(Returns!D138/Returns!D102)-1 -> 0.80994985 | E9: =(Returns!E138/Returns!E102)-1 -> 0.74036496
C10: 4 Year | D10: =(Returns!D138/Returns!D90)-1 -> 0.66925405 | E10: =(Returns!E138/Returns!E90)-1 -> 0.57969928 | H10: Active | I10: =D7-E7 -> 0.013546027
C11: 5 Year | D11: =(Returns!D138/Returns!D78)-1 -> 0.94174401 | E11: =(Returns!E138/Returns!E78)-1 -> 0.81297245
C12: CAGR | D12: =(Returns!D138/Returns!D5)^(1/10)-1 -> 0.15328524 | E12: =(Returns!E138/Returns!E5)^(1/10)-1 -> 0.1322717

Sheet Pivot Tables
N1: Years (Date) | O1: (Multiple Items)
A3: Row Labels | B3: SPY | C3: S&P 500 | N3: Row Labels | O3: SPY | P3: S&P500
A4: 2015 | B4: 12432.874 | C4: 12342.493 | N4: 45658 | O4: 0.030312468 | P4: 0.027016304
A5: 2016 | B5: 13027.815 | C5: 12666.695 | N5: 45689 | O5: -0.012694736 | P5: -0.014242093
A6: 2017 | B6: 15560.411 | C6: 14828.345 | N6: 45717 | O6: -0.058551336 | P6: -0.057544698
A7: 2018 | B7: 17600.764 | C7: 16471.637 | N7: 45748 | O7: -0.0056880327 | P7: -0.0076249433
A8: 2019 | B8: 19247.489 | C8: 17672.039 | N8: 45778 | O8: 0.062845018 | P8: 0.061523826
A9: 2020 | B9: 21484.277 | C9: 19350.197 | N9: 45809 | O9: 0.048287009 | P9: 0.049606839
A10: 2021 | B10: 29012.114 | C10: 25737.021 | N10: 45839 | O10: 0.026055914 | P10: 0.021666563
A11: 2022 | B11: 28025.38 | C11: 24527.371 | N11: 45870 | O11: 0.020519591 | P11: 0.019066444
A12: 2023 | B12: 30207.331 | C12: 26001.058 | N12: 45901 | O12: 0.03275709 | P12: 0.035323687
A13: 2024 | B13: 38683.459 | C13: 32843.568 | N13: 45931 | O13: 0.026676009 | P13: 0.022686872
A14: 2025 | B14: 45012.545 | C14: 37752.31 | N14: 45962 | O14: 0.0019499283 | P14: 0.0012996182
A15: 2026 | B15: 8340.5865 | C15: 6941.6587 | N15: 45992 | O15: -0.002151084 | P15: -0.00052413442
A16: Grand Total | B16: 278635.04 | C16: 247134.39 | N16: 46023 | O16: 0.017736268 | P16: 0.013662959
N17: 46054 | O17: -0.0036706478 | P17: -0.0042541999
E22: Row Labels | F22: SPY | G22: S&P500 | Q22: Row Labels | R22: Sum of Active_Return
E23: 42005 | Q23: 2015 | R23: 0.013411767
E24: 42036 | Q24: 2016 | R24: 0.02192822
E25: 42064 | Q25: 2017 | R25: 0.020298035
E26: 42095 | Q26: 2018 | R26: 0.017442805
E27: 42125 | Q27: 2019 | R27: 0.019538954
E28: 42156 | Q28: 2020 | R28: 0.019753235
E29: 42186 | Q29: 2021 | R29: 0.01574372
E30: 42217 | Q30: 2022 | R30: 0.015649582
E31: 42248 | Q31: 2023 | R31: 0.01646547
E32: 42278 | Q32: 2024 | R32: 0.013488257
E33: 42309 | Q33: 2025 | R33: 0.012063552
E34: 42339 | Q34: 2026 | R34: 0.0046568616
E35: 42370 | F35: -0.0086864921 | G35: -0.027443747 | Q35: Grand Total | R35: 0.19044046
E36: 42401 | F36: -0.062212861 | G36: -0.081857933
E37: 42430 | F37: 0.016136471 | G37: -0.0039411684
E38: 42461 | F38: 0.010904763 | G38: -0.0096906564
E39: 42491 | F39: 0.015051988 | G39: -0.0049539677
E40: 42522 | F40: 0.039351003 | G40: 0.017328207
E41: 42552 | F41: 0.053813261 | G41: 0.033158418
E42: 42583 | F42: 0.12355594 | G42: 0.10078689
E43: 42614 | F43: 0.15321087 | G43: 0.12928964
E44: 42644 | F44: 0.044229885 | G44: 0.022502016
E45: 42675 | F45: 0.078754164 | G45: 0.056911932
...

Sheet Dashboard
A1: SPY vs S&P 500 Performance Dashboard
A2: Period: Jan 2015 – Jan 2026 | Frequency: Monthly
S23: Metric | T23: SPY | U23: S&P 500 | V23: SPY vs S&P 500
S24: YTD | T24: -0.0036706478 | U24: -0.0042541999 | V24: =Table5[[#This Row],[SPY]]-Table5[[#This Row],[S&P 500]] -> 0.00058355209
S25: 1 Year | T25: 0.17393057 | U25: 0.16038454 | V25: =Table5[[#This Row],[SPY]]-Table5[[#This Row],[S&P 500]] -> 0.013546027
S27: 2 Year | T27: 0.3904768 | U27: 0.35579742 | V27: =Table5[[#This Row],[SPY]]-Table5[[#This Row],[S&P 500]] -> 0.034679374
S29: 3 Year | T29: 0.80994985 | U29: 0.74036496 | V29: =Table5[[#This Row],[SPY]]-Table5[[#This Row],[S&P 500]] -> 0.069584893
S31: 4 Year | T31: 0.66925405 | U31: 0.57969928 | V31: =Table5[[#This Row],[SPY]]-Table5[[#This Row],[S&P 500]] -> 0.089554775
S33: 5 Year | T33: 0.94174401 | U33: 0.81297245 | V33: =Table5[[#This Row],[SPY]]-Table5[[#This Row],[S&P 500]] -> 0.12877156
S35: CAGR | T35: 0.15328524 | U35: 0.1322717 | V35: =Table5[[#This Row],[SPY]]-Table5[[#This Row],[S&P 500]] -> 0.021013539
A37: Source: Yahoo Finance | Monthly Adjusted Close
